<?xml version="1.0" encoding="UTF-8"?>
<!-- Generated by org.testng.reporters.JUnitXMLReporter -->
<testsuite hostname="Automata" ignored="0" name="Test" tests="2" failures="1" timestamp="06 May 2018 05:46:20 GMT" time="31.999" errors="0">
  <testcase name="shippingTest" time="6.037" classname="MavenProject.UpsTest"/>
  <testcase name="signUpTest" time="4.123" classname="MavenProject.UpsTest">
    <failure type="java.lang.AssertionError" message="expected [You already have a ups.com ID linked to this email address. If you continue, you&amp;apos;ll need to log in with your new user ID to access this] but found [You already have a ups.com ID linked to this email address. If you continue, you&amp;apos;ll need to log in with your new user ID to access this profile.
Send a list of My User IDs]">
      <![CDATA[java.lang.AssertionError: expected [You already have a ups.com ID linked to this email address. If you continue, you'll need to log in with your new user ID to access this] but found [You already have a ups.com ID linked to this email address. If you continue, you'll need to log in with your new user ID to access this profile.
Send a list of My User IDs]
at MavenProject.UpsTest.signUpTest(UpsTest.java:70)
... Removed 31 stack frames]]>
    </failure>
  </testcase> <!-- signUpTest -->
</testsuite> <!-- Test -->
